[2022-11-06T22:28:11.908-0300] {taskinstance.py:1165} INFO - Dependencies all met for <TaskInstance: xcom_dag.analyze_data manual__2022-11-07T01:22:54.171084+00:00 [queued]>
[2022-11-06T22:28:11.922-0300] {taskinstance.py:1165} INFO - Dependencies all met for <TaskInstance: xcom_dag.analyze_data manual__2022-11-07T01:22:54.171084+00:00 [queued]>
[2022-11-06T22:28:11.923-0300] {taskinstance.py:1362} INFO - 
--------------------------------------------------------------------------------
[2022-11-06T22:28:11.923-0300] {taskinstance.py:1363} INFO - Starting attempt 2 of 2
[2022-11-06T22:28:11.923-0300] {taskinstance.py:1364} INFO - 
--------------------------------------------------------------------------------
[2022-11-06T22:28:11.947-0300] {taskinstance.py:1383} INFO - Executing <Task(PythonOperator): analyze_data> on 2022-11-07 01:22:54.171084+00:00
[2022-11-06T22:28:11.963-0300] {standard_task_runner.py:55} INFO - Started process 36384 to run task
[2022-11-06T22:28:11.971-0300] {standard_task_runner.py:82} INFO - Running: ['airflow', 'tasks', 'run', 'xcom_dag', 'analyze_data', 'manual__2022-11-07T01:22:54.171084+00:00', '--job-id', '529', '--raw', '--subdir', 'DAGS_FOLDER/dag_selenium.py', '--cfg-path', '/tmp/tmp28kyduhz']
[2022-11-06T22:28:11.973-0300] {standard_task_runner.py:83} INFO - Job 529: Subtask analyze_data
[2022-11-06T22:28:12.141-0300] {task_command.py:376} INFO - Running <TaskInstance: xcom_dag.analyze_data manual__2022-11-07T01:22:54.171084+00:00 [running]> on host debian
[2022-11-06T22:28:12.378-0300] {taskinstance.py:1590} INFO - Exporting the following env vars:
AIRFLOW_CTX_DAG_OWNER=airflow
AIRFLOW_CTX_DAG_ID=xcom_dag
AIRFLOW_CTX_TASK_ID=analyze_data
AIRFLOW_CTX_EXECUTION_DATE=2022-11-07T01:22:54.171084+00:00
AIRFLOW_CTX_TRY_NUMBER=2
AIRFLOW_CTX_DAG_RUN_ID=manual__2022-11-07T01:22:54.171084+00:00
[2022-11-06T22:28:12.401-0300] {taskinstance.py:1851} ERROR - Task failed with exception
Traceback (most recent call last):
  File "/home/debian/etlhausz/venv/lib/python3.9/site-packages/airflow/operators/python.py", line 175, in execute
    return_value = self.execute_callable()
  File "/home/debian/etlhausz/venv/lib/python3.9/site-packages/airflow/operators/python.py", line 193, in execute_callable
    return self.python_callable(*self.op_args, **self.op_kwargs)
  File "/home/debian/etlhausz/airflow/dags/dag_selenium.py", line 56, in analyze_testing_increases
    for t in testing_increases:
TypeError: 'NoneType' object is not iterable
[2022-11-06T22:28:12.417-0300] {taskinstance.py:1401} INFO - Marking task as FAILED. dag_id=xcom_dag, task_id=analyze_data, execution_date=20221107T012254, start_date=20221107T012811, end_date=20221107T012812
[2022-11-06T22:28:12.427-0300] {standard_task_runner.py:100} ERROR - Failed to execute job 529 for task analyze_data ('NoneType' object is not iterable; 36384)
[2022-11-06T22:28:12.462-0300] {local_task_job.py:164} INFO - Task exited with return code 1
[2022-11-06T22:28:12.501-0300] {local_task_job.py:273} INFO - 0 downstream tasks scheduled from follow-on schedule check
