[2022-11-06T17:02:14.636-0300] {taskinstance.py:1165} INFO - Dependencies all met for <TaskInstance: get_urls_deca.get_produtos scheduled__2022-11-06T19:52:04.351167+00:00 [queued]>
[2022-11-06T17:02:14.672-0300] {taskinstance.py:1165} INFO - Dependencies all met for <TaskInstance: get_urls_deca.get_produtos scheduled__2022-11-06T19:52:04.351167+00:00 [queued]>
[2022-11-06T17:02:14.672-0300] {taskinstance.py:1362} INFO - 
--------------------------------------------------------------------------------
[2022-11-06T17:02:14.673-0300] {taskinstance.py:1363} INFO - Starting attempt 1 of 1
[2022-11-06T17:02:14.673-0300] {taskinstance.py:1364} INFO - 
--------------------------------------------------------------------------------
[2022-11-06T17:02:14.689-0300] {taskinstance.py:1383} INFO - Executing <Task(PythonOperator): get_produtos> on 2022-11-06 19:52:04.351167+00:00
[2022-11-06T17:02:14.698-0300] {standard_task_runner.py:55} INFO - Started process 19282 to run task
[2022-11-06T17:02:14.701-0300] {standard_task_runner.py:82} INFO - Running: ['airflow', 'tasks', 'run', 'get_urls_deca', 'get_produtos', 'scheduled__2022-11-06T19:52:04.351167+00:00', '--job-id', '394', '--raw', '--subdir', 'DAGS_FOLDER/teste_excom.py', '--cfg-path', '/tmp/tmpimygz2nz']
[2022-11-06T17:02:14.702-0300] {standard_task_runner.py:83} INFO - Job 394: Subtask get_produtos
[2022-11-06T17:02:14.921-0300] {task_command.py:376} INFO - Running <TaskInstance: get_urls_deca.get_produtos scheduled__2022-11-06T19:52:04.351167+00:00 [running]> on host debian
[2022-11-06T17:02:15.090-0300] {taskinstance.py:1590} INFO - Exporting the following env vars:
AIRFLOW_CTX_DAG_OWNER=airflow
AIRFLOW_CTX_DAG_ID=get_urls_deca
AIRFLOW_CTX_TASK_ID=get_produtos
AIRFLOW_CTX_EXECUTION_DATE=2022-11-06T19:52:04.351167+00:00
AIRFLOW_CTX_TRY_NUMBER=1
AIRFLOW_CTX_DAG_RUN_ID=scheduled__2022-11-06T19:52:04.351167+00:00
[2022-11-06T17:02:15.125-0300] {taskinstance.py:1851} ERROR - Task failed with exception
Traceback (most recent call last):
  File "/home/debian/etlhausz/venv/lib/python3.9/site-packages/airflow/operators/python.py", line 175, in execute
    return_value = self.execute_callable()
  File "/home/debian/etlhausz/venv/lib/python3.9/site-packages/airflow/operators/python.py", line 193, in execute_callable
    return self.python_callable(*self.op_args, **self.op_kwargs)
  File "/home/debian/etlhausz/airflow/dags/teste_excom.py", line 81, in _storing_models
    data = pd.DataFrame(lista)
UnboundLocalError: local variable 'lista' referenced before assignment
[2022-11-06T17:02:15.146-0300] {taskinstance.py:1401} INFO - Marking task as FAILED. dag_id=get_urls_deca, task_id=get_produtos, execution_date=20221106T195204, start_date=20221106T200214, end_date=20221106T200215
[2022-11-06T17:02:15.189-0300] {standard_task_runner.py:100} ERROR - Failed to execute job 394 for task get_produtos (local variable 'lista' referenced before assignment; 19282)
[2022-11-06T17:02:15.205-0300] {local_task_job.py:164} INFO - Task exited with return code 1
[2022-11-06T17:02:15.241-0300] {local_task_job.py:273} INFO - 0 downstream tasks scheduled from follow-on schedule check
