[2022-11-06T18:38:14.016-0300] {taskinstance.py:1165} INFO - Dependencies all met for <TaskInstance: dagselenium.transform manual__2022-11-06T21:37:58.502412+00:00 [queued]>
[2022-11-06T18:38:14.031-0300] {taskinstance.py:1165} INFO - Dependencies all met for <TaskInstance: dagselenium.transform manual__2022-11-06T21:37:58.502412+00:00 [queued]>
[2022-11-06T18:38:14.031-0300] {taskinstance.py:1362} INFO - 
--------------------------------------------------------------------------------
[2022-11-06T18:38:14.031-0300] {taskinstance.py:1363} INFO - Starting attempt 1 of 3
[2022-11-06T18:38:14.031-0300] {taskinstance.py:1364} INFO - 
--------------------------------------------------------------------------------
[2022-11-06T18:38:14.069-0300] {taskinstance.py:1383} INFO - Executing <Task(PythonOperator): transform> on 2022-11-06 21:37:58.502412+00:00
[2022-11-06T18:38:14.077-0300] {standard_task_runner.py:55} INFO - Started process 63464 to run task
[2022-11-06T18:38:14.087-0300] {standard_task_runner.py:82} INFO - Running: ['airflow', 'tasks', 'run', 'dagselenium', 'transform', 'manual__2022-11-06T21:37:58.502412+00:00', '--job-id', '451', '--raw', '--subdir', 'DAGS_FOLDER/teste_excom.py', '--cfg-path', '/tmp/tmphmu2e58c']
[2022-11-06T18:38:14.088-0300] {standard_task_runner.py:83} INFO - Job 451: Subtask transform
[2022-11-06T18:38:14.676-0300] {task_command.py:376} INFO - Running <TaskInstance: dagselenium.transform manual__2022-11-06T21:37:58.502412+00:00 [running]> on host debian
[2022-11-06T18:38:14.994-0300] {taskinstance.py:1590} INFO - Exporting the following env vars:
AIRFLOW_CTX_DAG_OWNER=airflow
AIRFLOW_CTX_DAG_ID=dagselenium
AIRFLOW_CTX_TASK_ID=transform
AIRFLOW_CTX_EXECUTION_DATE=2022-11-06T21:37:58.502412+00:00
AIRFLOW_CTX_TRY_NUMBER=1
AIRFLOW_CTX_DAG_RUN_ID=manual__2022-11-06T21:37:58.502412+00:00
[2022-11-06T18:38:15.102-0300] {taskinstance.py:1851} ERROR - Task failed with exception
Traceback (most recent call last):
  File "/home/debian/etlhausz/venv/lib/python3.9/site-packages/airflow/operators/python.py", line 175, in execute
    return_value = self.execute_callable()
  File "/home/debian/etlhausz/venv/lib/python3.9/site-packages/airflow/operators/python.py", line 193, in execute_callable
    return self.python_callable(*self.op_args, **self.op_kwargs)
  File "/home/debian/etlhausz/airflow/dags/teste_excom.py", line 68, in transform
    for orders in extract_data_string:
TypeError: 'NoneType' object is not iterable
[2022-11-06T18:38:15.140-0300] {taskinstance.py:1401} INFO - Marking task as UP_FOR_RETRY. dag_id=dagselenium, task_id=transform, execution_date=20221106T213758, start_date=20221106T213814, end_date=20221106T213815
[2022-11-06T18:38:15.316-0300] {standard_task_runner.py:100} ERROR - Failed to execute job 451 for task transform ('NoneType' object is not iterable; 63464)
[2022-11-06T18:38:15.337-0300] {local_task_job.py:164} INFO - Task exited with return code 1
[2022-11-06T18:38:15.420-0300] {local_task_job.py:273} INFO - 0 downstream tasks scheduled from follow-on schedule check
