[2022-11-06T18:47:22.692-0300] {taskinstance.py:1165} INFO - Dependencies all met for <TaskInstance: dagselenium.transform manual__2022-11-06T21:41:59.644036+00:00 [queued]>
[2022-11-06T18:47:22.755-0300] {taskinstance.py:1165} INFO - Dependencies all met for <TaskInstance: dagselenium.transform manual__2022-11-06T21:41:59.644036+00:00 [queued]>
[2022-11-06T18:47:22.755-0300] {taskinstance.py:1362} INFO - 
--------------------------------------------------------------------------------
[2022-11-06T18:47:22.755-0300] {taskinstance.py:1363} INFO - Starting attempt 2 of 3
[2022-11-06T18:47:22.755-0300] {taskinstance.py:1364} INFO - 
--------------------------------------------------------------------------------
[2022-11-06T18:47:22.865-0300] {taskinstance.py:1383} INFO - Executing <Task(PythonOperator): transform> on 2022-11-06 21:41:59.644036+00:00
[2022-11-06T18:47:22.890-0300] {standard_task_runner.py:55} INFO - Started process 74509 to run task
[2022-11-06T18:47:22.928-0300] {standard_task_runner.py:82} INFO - Running: ['airflow', 'tasks', 'run', 'dagselenium', 'transform', 'manual__2022-11-06T21:41:59.644036+00:00', '--job-id', '457', '--raw', '--subdir', 'DAGS_FOLDER/teste_excom.py', '--cfg-path', '/tmp/tmpb9ea6vtz']
[2022-11-06T18:47:22.931-0300] {standard_task_runner.py:83} INFO - Job 457: Subtask transform
[2022-11-06T18:47:23.184-0300] {task_command.py:376} INFO - Running <TaskInstance: dagselenium.transform manual__2022-11-06T21:41:59.644036+00:00 [running]> on host debian
[2022-11-06T18:47:23.385-0300] {taskinstance.py:1590} INFO - Exporting the following env vars:
AIRFLOW_CTX_DAG_OWNER=airflow
AIRFLOW_CTX_DAG_ID=dagselenium
AIRFLOW_CTX_TASK_ID=transform
AIRFLOW_CTX_EXECUTION_DATE=2022-11-06T21:41:59.644036+00:00
AIRFLOW_CTX_TRY_NUMBER=2
AIRFLOW_CTX_DAG_RUN_ID=manual__2022-11-06T21:41:59.644036+00:00
[2022-11-06T18:47:23.428-0300] {taskinstance.py:1851} ERROR - Task failed with exception
Traceback (most recent call last):
  File "/home/debian/etlhausz/venv/lib/python3.9/site-packages/airflow/operators/python.py", line 175, in execute
    return_value = self.execute_callable()
  File "/home/debian/etlhausz/venv/lib/python3.9/site-packages/airflow/operators/python.py", line 193, in execute_callable
    return self.python_callable(*self.op_args, **self.op_kwargs)
  File "/home/debian/etlhausz/airflow/dags/teste_excom.py", line 68, in transform
    for orders in extract_data_string:
TypeError: 'NoneType' object is not iterable
[2022-11-06T18:47:23.490-0300] {taskinstance.py:1401} INFO - Marking task as UP_FOR_RETRY. dag_id=dagselenium, task_id=transform, execution_date=20221106T214159, start_date=20221106T214722, end_date=20221106T214723
[2022-11-06T18:47:23.514-0300] {standard_task_runner.py:100} ERROR - Failed to execute job 457 for task transform ('NoneType' object is not iterable; 74509)
[2022-11-06T18:47:23.536-0300] {local_task_job.py:164} INFO - Task exited with return code 1
[2022-11-06T18:47:23.566-0300] {local_task_job.py:273} INFO - 0 downstream tasks scheduled from follow-on schedule check
