[2022-11-06T22:01:50.549-0300] {taskinstance.py:1165} INFO - Dependencies all met for <TaskInstance: selenium_dag.get_testing_increase scheduled__2022-11-06T00:00:00+00:00 [queued]>
[2022-11-06T22:01:50.618-0300] {taskinstance.py:1165} INFO - Dependencies all met for <TaskInstance: selenium_dag.get_testing_increase scheduled__2022-11-06T00:00:00+00:00 [queued]>
[2022-11-06T22:01:50.618-0300] {taskinstance.py:1362} INFO - 
--------------------------------------------------------------------------------
[2022-11-06T22:01:50.618-0300] {taskinstance.py:1363} INFO - Starting attempt 1 of 1
[2022-11-06T22:01:50.618-0300] {taskinstance.py:1364} INFO - 
--------------------------------------------------------------------------------
[2022-11-06T22:01:50.689-0300] {taskinstance.py:1383} INFO - Executing <Task(_PythonDecoratedOperator): get_testing_increase> on 2022-11-06 00:00:00+00:00
[2022-11-06T22:01:50.718-0300] {standard_task_runner.py:55} INFO - Started process 5392 to run task
[2022-11-06T22:01:50.758-0300] {standard_task_runner.py:82} INFO - Running: ['airflow', 'tasks', 'run', 'selenium_dag', 'get_testing_increase', 'scheduled__2022-11-06T00:00:00+00:00', '--job-id', '520', '--raw', '--subdir', 'DAGS_FOLDER/dag_selenium.py', '--cfg-path', '/tmp/tmpuuz6za_t']
[2022-11-06T22:01:50.758-0300] {standard_task_runner.py:83} INFO - Job 520: Subtask get_testing_increase
[2022-11-06T22:01:51.191-0300] {task_command.py:376} INFO - Running <TaskInstance: selenium_dag.get_testing_increase scheduled__2022-11-06T00:00:00+00:00 [running]> on host debian
[2022-11-06T22:01:51.626-0300] {taskinstance.py:1590} INFO - Exporting the following env vars:
AIRFLOW_CTX_DAG_OWNER=airflow
AIRFLOW_CTX_DAG_ID=selenium_dag
AIRFLOW_CTX_TASK_ID=get_testing_increase
AIRFLOW_CTX_EXECUTION_DATE=2022-11-06T00:00:00+00:00
AIRFLOW_CTX_TRY_NUMBER=1
AIRFLOW_CTX_DAG_RUN_ID=scheduled__2022-11-06T00:00:00+00:00
[2022-11-06T22:01:51.627-0300] {taskinstance.py:1851} ERROR - Task failed with exception
Traceback (most recent call last):
  File "/home/debian/etlhausz/venv/lib/python3.9/site-packages/airflow/decorators/base.py", line 188, in execute
    return_value = super().execute(context)
  File "/home/debian/etlhausz/venv/lib/python3.9/site-packages/airflow/operators/python.py", line 175, in execute
    return_value = self.execute_callable()
  File "/home/debian/etlhausz/venv/lib/python3.9/site-packages/airflow/operators/python.py", line 193, in execute_callable
    return self.python_callable(*self.op_args, **self.op_kwargs)
  File "/home/debian/etlhausz/airflow/dags/dag_selenium.py", line 46, in get_testing_increase
    driver.get(url)
UnboundLocalError: local variable 'url' referenced before assignment
[2022-11-06T22:01:51.716-0300] {taskinstance.py:1401} INFO - Marking task as FAILED. dag_id=selenium_dag, task_id=get_testing_increase, execution_date=20221106T000000, start_date=20221107T010150, end_date=20221107T010151
[2022-11-06T22:01:51.815-0300] {standard_task_runner.py:100} ERROR - Failed to execute job 520 for task get_testing_increase (local variable 'url' referenced before assignment; 5392)
[2022-11-06T22:01:51.862-0300] {local_task_job.py:164} INFO - Task exited with return code 1
[2022-11-06T22:01:51.960-0300] {local_task_job.py:273} INFO - 0 downstream tasks scheduled from follow-on schedule check
[2022-11-06T22:03:44.589-0300] {taskinstance.py:1165} INFO - Dependencies all met for <TaskInstance: selenium_dag.get_testing_increase scheduled__2022-11-06T00:00:00+00:00 [queued]>
[2022-11-06T22:03:44.597-0300] {taskinstance.py:1165} INFO - Dependencies all met for <TaskInstance: selenium_dag.get_testing_increase scheduled__2022-11-06T00:00:00+00:00 [queued]>
[2022-11-06T22:03:44.598-0300] {taskinstance.py:1362} INFO - 
--------------------------------------------------------------------------------
[2022-11-06T22:03:44.598-0300] {taskinstance.py:1363} INFO - Starting attempt 1 of 1
[2022-11-06T22:03:44.598-0300] {taskinstance.py:1364} INFO - 
--------------------------------------------------------------------------------
[2022-11-06T22:03:44.609-0300] {taskinstance.py:1383} INFO - Executing <Task(_PythonDecoratedOperator): get_testing_increase> on 2022-11-06 00:00:00+00:00
[2022-11-06T22:03:44.615-0300] {standard_task_runner.py:55} INFO - Started process 7567 to run task
[2022-11-06T22:03:44.621-0300] {standard_task_runner.py:82} INFO - Running: ['airflow', 'tasks', 'run', 'selenium_dag', 'get_testing_increase', 'scheduled__2022-11-06T00:00:00+00:00', '--job-id', '521', '--raw', '--subdir', 'DAGS_FOLDER/dag_selenium.py', '--cfg-path', '/tmp/tmp70dyd_yc']
[2022-11-06T22:03:44.621-0300] {standard_task_runner.py:83} INFO - Job 521: Subtask get_testing_increase
[2022-11-06T22:03:44.744-0300] {task_command.py:376} INFO - Running <TaskInstance: selenium_dag.get_testing_increase scheduled__2022-11-06T00:00:00+00:00 [running]> on host debian
[2022-11-06T22:03:44.833-0300] {taskinstance.py:1590} INFO - Exporting the following env vars:
AIRFLOW_CTX_DAG_OWNER=airflow
AIRFLOW_CTX_DAG_ID=selenium_dag
AIRFLOW_CTX_TASK_ID=get_testing_increase
AIRFLOW_CTX_EXECUTION_DATE=2022-11-06T00:00:00+00:00
AIRFLOW_CTX_TRY_NUMBER=1
AIRFLOW_CTX_DAG_RUN_ID=scheduled__2022-11-06T00:00:00+00:00
[2022-11-06T22:03:44.834-0300] {taskinstance.py:1851} ERROR - Task failed with exception
Traceback (most recent call last):
  File "/home/debian/etlhausz/venv/lib/python3.9/site-packages/airflow/decorators/base.py", line 188, in execute
    return_value = super().execute(context)
  File "/home/debian/etlhausz/venv/lib/python3.9/site-packages/airflow/operators/python.py", line 175, in execute
    return_value = self.execute_callable()
  File "/home/debian/etlhausz/venv/lib/python3.9/site-packages/airflow/operators/python.py", line 193, in execute_callable
    return self.python_callable(*self.op_args, **self.op_kwargs)
  File "/home/debian/etlhausz/airflow/dags/dag_selenium.py", line 46, in get_testing_increase
    driver.get(url)
UnboundLocalError: local variable 'url' referenced before assignment
[2022-11-06T22:03:44.848-0300] {taskinstance.py:1401} INFO - Marking task as FAILED. dag_id=selenium_dag, task_id=get_testing_increase, execution_date=20221106T000000, start_date=20221107T010344, end_date=20221107T010344
[2022-11-06T22:03:44.859-0300] {standard_task_runner.py:100} ERROR - Failed to execute job 521 for task get_testing_increase (local variable 'url' referenced before assignment; 7567)
[2022-11-06T22:03:44.881-0300] {local_task_job.py:164} INFO - Task exited with return code 1
[2022-11-06T22:03:44.916-0300] {local_task_job.py:273} INFO - 0 downstream tasks scheduled from follow-on schedule check
